<?xml version="1.0" ?>
<!-- =================================================================================== -->
<!-- |    This document was autogenerated by xacro from spidy.xacro                    | -->
<!-- |    EDITING THIS FILE BY HAND IS NOT RECOMMENDED                                 | -->
<!-- =================================================================================== -->
<robot name="spiderbot">
  <!-- Added by ChatGPT: leg color materials -->
  <material name="front_green">
    <color rgba="0.1 0.8 0.1 1.0"/>
  </material>
  <material name="rear_red">
    <color rgba="0.9 0.1 0.1 1.0"/>
  </material>
  <!-- ============================================ -->
  <!-- MATERIALS -->
  <!-- ============================================ -->
  <material name="silver">
    <color rgba="0.700 0.700 0.700 1.000"/>
  </material>
  <material name="black">
    <color rgba="0.2 0.2 0.2 1.0"/>
  </material>
  <!-- ============================================ -->
  <!-- BASE LINK -->
  <!-- ============================================ -->
  <link name="base_link">
    <inertial>
      <origin rpy="0 0 0" xyz="-0.019978371341620418 -0.020000000835769374 -0.10495599955384616"/>
      <mass value="4.731408299822953"/>
      <inertia ixx="0.018448" ixy="7e-06" ixz="2e-06" iyy="0.023393" iyz="0.0" izz="0.038341"/>
    </inertial>
    <visual>
      <origin rpy="0 0 0" xyz="0 0 0"/>
      <geometry>
        <mesh filename="package://spiderbot_description/meshes/base_link.stl" scale="0.001 0.001 0.001"/>
      </geometry>
      <material name="silver"/>
    </visual>
    <collision>
      <origin rpy="0 0 0" xyz="0 0 0"/>
      <geometry>
        <mesh filename="package://spiderbot_description/meshes/base_link.stl" scale="0.001 0.001 0.001"/>
      </geometry>
    </collision>
  </link>
  <!-- ============================================ -->
  <!-- FRONT LEFT LEG -->
  <!-- ============================================ -->
  <link name="fl_coxa_link">
    <inertial>
      <origin rpy="0 0 0" xyz="0.028135954876008673 -0.029329745571449628 -0.028119170695013032"/>
      <mass value="0.542887385601251"/>
      <inertia ixx="0.000264" ixy="3e-05" ixz="1e-06" iyy="0.000279" iyz="1e-05" izz="0.00019"/>
    </inertial>
    <visual>
      <origin rpy="0 0 0" xyz="-0.0802 0.1049 0.0717"/>
      <geometry>
        <mesh filename="package://spiderbot_description/meshes/coxa_FL_1.stl" scale="0.001 0.001 0.001"/>
      </geometry>
      <material name="front_green"/>
    </visual>
    <collision>
      <origin rpy="0 0 0" xyz="-0.0802 0.1049 0.0717"/>
      <geometry>
        <mesh filename="package://spiderbot_description/meshes/coxa_FL_1.stl" scale="0.001 0.001 0.001"/>
      </geometry>
    </collision>
  </link>
  <link name="fl_femur_link">
    <inertial>
      <origin rpy="0 0 0" xyz="0.006997567200805632 -0.04957052602340402 -7.856501144098971e-10"/>
      <mass value="0.3492287921483335"/>
      <inertia ixx="0.000188" ixy="-1.9e-05" ixz="0.0" iyy="0.000188" iyz="-0.0" izz="0.000352"/>
    </inertial>
    <visual>
      <origin rpy="0 0 0" xyz="-0.135496 0.120881 0.0888"/>
      <geometry>
        <mesh filename="package://spiderbot_description/meshes/femur_FL_1.stl" scale="0.001 0.001 0.001"/>
      </geometry>
      <material name="front_green"/>
    </visual>
    <collision>
      <origin rpy="0 0 0" xyz="-0.135496 0.120881 0.0888"/>
      <geometry>
        <mesh filename="package://spiderbot_description/meshes/femur_FL_1.stl" scale="0.001 0.001 0.001"/>
      </geometry>
    </collision>
  </link>
  <link name="fl_tibia_link">
    <inertial>
      <origin rpy="0 0 0" xyz="-0.015570071022172616 -0.025956642235597044 -0.04429277038724115"/>
      <mass value="0.8577979430954783"/>
      <inertia ixx="0.0017" ixy="-1.3e-05" ixz="7.6e-05" iyy="0.001667" iyz="-6.5e-05" izz="0.000147"/>
    </inertial>
    <visual>
      <origin rpy="0 0 0" xyz="-0.192064 0.177449 0.0888"/>
      <geometry>
        <mesh filename="package://spiderbot_description/meshes/tibia_FL_1.stl" scale="0.001 0.001 0.001"/>
      </geometry>
      <material name="front_green"/>
    </visual>
    <collision>
      <origin rpy="0 0 0" xyz="-0.192064 0.177449 0.0888"/>
      <geometry>
        <mesh filename="package://spiderbot_description/meshes/tibia_FL_1.stl" scale="0.001 0.001 0.001"/>
      </geometry>
    </collision>
  </link>
  <!-- ============================================ -->
  <!-- FRONT RIGHT LEG -->
  <!-- ============================================ -->
  <link name="fr_coxa_link">
    <inertial>
      <origin rpy="0 0 0" xyz="-0.029329745571448573 -0.028135954876009714 -0.028119170695013046"/>
      <mass value="0.542887385601251"/>
      <inertia ixx="0.000279" ixy="-3e-05" ixz="1e-05" iyy="0.000264" iyz="-1e-06" izz="0.00019"/>
    </inertial>
    <visual>
      <origin rpy="0 0 0" xyz="0.1202 0.10365 0.07235"/>
      <geometry>
        <mesh filename="package://spiderbot_description/meshes/coxa_FR_1.stl" scale="0.001 0.001 0.001"/>
      </geometry>
      <material name="front_green"/>
    </visual>
    <collision>
      <origin rpy="0 0 0" xyz="0.1202 0.10365 0.07235"/>
      <geometry>
        <mesh filename="package://spiderbot_description/meshes/coxa_FR_1.stl" scale="0.001 0.001 0.001"/>
      </geometry>
    </collision>
  </link>
  <link name="fr_femur_link">
    <inertial>
      <origin rpy="0 0 0" xyz="-0.048509678665941525 -0.008058040186904758 7.856502393099873e-10"/>
      <mass value="0.3492287921483335"/>
      <inertia ixx="0.000188" ixy="1.9e-05" ixz="-0.0" iyy="0.000188" iyz="-0.0" izz="0.000352"/>
    </inertial>
    <visual>
      <origin rpy="0 0 0" xyz="0.136181 0.158946 0.08945"/>
      <geometry>
        <mesh filename="package://spiderbot_description/meshes/femur_FR_1.stl" scale="0.001 0.001 0.001"/>
      </geometry>
      <material name="front_green"/>
    </visual>
    <collision>
      <origin rpy="0 0 0" xyz="0.136181 0.158946 0.08945"/>
      <geometry>
        <mesh filename="package://spiderbot_description/meshes/femur_FR_1.stl" scale="0.001 0.001 0.001"/>
      </geometry>
    </collision>
  </link>
  <link name="fr_tibia_link">
    <inertial>
      <origin rpy="0 0 0" xyz="-0.025956982063816164 0.015570410850391847 -0.04429277038724089"/>
      <mass value="0.8577979430954783"/>
      <inertia ixx="0.001667" ixy="1.3e-05" ixz="-6.5e-05" iyy="0.0017" iyz="-7.6e-05" izz="0.000147"/>
    </inertial>
    <visual>
      <origin rpy="0 0 0" xyz="0.191688 0.216575 0.08945"/>
      <geometry>
        <mesh filename="package://spiderbot_description/meshes/tibia_FR_1.stl" scale="0.001 0.001 0.001"/>
      </geometry>
      <material name="front_green"/>
    </visual>
    <collision>
      <origin rpy="0 0 0" xyz="0.191688 0.216575 0.08945"/>
      <geometry>
        <mesh filename="package://spiderbot_description/meshes/tibia_FR_1.stl" scale="0.001 0.001 0.001"/>
      </geometry>
    </collision>
  </link>
  <!-- ============================================ -->
  <!-- REAR LEFT LEG -->
  <!-- ============================================ -->
  <link name="rl_coxa_link">
    <inertial>
      <origin rpy="0 0 0" xyz="0.029329745571448476 0.028135954876009367 -0.028119170695013004"/>
      <mass value="0.542887385601251"/>
      <inertia ixx="0.000279" ixy="-3e-05" ixz="-1e-05" iyy="0.000264" iyz="1e-06" izz="0.00019"/>
    </inertial>
    <visual>
      <origin rpy="0 0 0" xyz="-0.0802 -0.0649 0.0717"/>
      <geometry>
        <mesh filename="package://spiderbot_description/meshes/coxa_RL_1.stl" scale="0.001 0.001 0.001"/>
      </geometry>
      <material name="rear_red"/>
    </visual>
    <collision>
      <origin rpy="0 0 0" xyz="-0.0802 -0.0649 0.0717"/>
      <geometry>
        <mesh filename="package://spiderbot_description/meshes/coxa_RL_1.stl" scale="0.001 0.001 0.001"/>
      </geometry>
    </collision>
  </link>
  <link name="rl_femur_link">
    <inertial>
      <origin rpy="0 0 0" xyz="0.049570338837721176 0.006997380015124621 7.856499478764434e-10"/>
      <mass value="0.3492287921483335"/>
      <inertia ixx="0.000188" ixy="1.9e-05" ixz="0.0" iyy="0.000188" iyz="0.0" izz="0.000352"/>
    </inertial>
    <visual>
      <origin rpy="0 0 0" xyz="-0.096181 -0.120196 0.0888"/>
      <geometry>
        <mesh filename="package://spiderbot_description/meshes/femur_RL_1.stl" scale="0.001 0.001 0.001"/>
      </geometry>
      <material name="rear_red"/>
    </visual>
    <collision>
      <origin rpy="0 0 0" xyz="-0.096181 -0.120196 0.0888"/>
      <geometry>
        <mesh filename="package://spiderbot_description/meshes/femur_RL_1.stl" scale="0.001 0.001 0.001"/>
      </geometry>
    </collision>
  </link>
  <link name="rl_tibia_link">
    <inertial>
      <origin rpy="0 0 0" xyz="0.025956642235595767 -0.01557007102217195 -0.04429277038724118"/>
      <mass value="0.8577979430954783"/>
      <inertia ixx="0.001667" ixy="1.3e-05" ixz="6.5e-05" iyy="0.0017" iyz="7.6e-05" izz="0.000147"/>
    </inertial>
    <visual>
      <origin rpy="0 0 0" xyz="-0.152749 -0.176764 0.0888"/>
      <geometry>
        <mesh filename="package://spiderbot_description/meshes/tibia_RL_1.stl" scale="0.001 0.001 0.001"/>
      </geometry>
      <material name="rear_red"/>
    </visual>
    <collision>
      <origin rpy="0 0 0" xyz="-0.152749 -0.176764 0.0888"/>
      <geometry>
        <mesh filename="package://spiderbot_description/meshes/tibia_RL_1.stl" scale="0.001 0.001 0.001"/>
      </geometry>
    </collision>
  </link>
  <!-- ============================================ -->
  <!-- REAR RIGHT LEG -->
  <!-- ============================================ -->
  <link name="rr_coxa_link">
    <inertial>
      <origin rpy="0 0 0" xyz="-0.028135954876008396 0.029329745571449795 -0.02661917069501303"/>
      <mass value="0.542887385601251"/>
      <inertia ixx="0.000264" ixy="3e-05" ixz="-1e-06" iyy="0.000279" iyz="-1e-05" izz="0.00019"/>
    </inertial>
    <visual>
      <origin rpy="0 0 0" xyz="0.1202 -0.0649 0.0717"/>
      <geometry>
        <mesh filename="package://spiderbot_description/meshes/coxa_RR_1.stl" scale="0.001 0.001 0.001"/>
      </geometry>
      <material name="rear_red"/>
    </visual>
    <collision>
      <origin rpy="0 0 0" xyz="0.1202 -0.0649 0.0717"/>
      <geometry>
        <mesh filename="package://spiderbot_description/meshes/coxa_RR_1.stl" scale="0.001 0.001 0.001"/>
      </geometry>
    </collision>
  </link>
  <link name="rr_femur_link">
    <inertial>
      <origin rpy="0 0 0" xyz="-0.006997380015123622 0.04957033883772251 7.856499617542312e-10"/>
      <mass value="0.3492287921483335"/>
      <inertia ixx="0.000188" ixy="-1.9e-05" ixz="-0.0" iyy="0.000188" iyz="0.0" izz="0.000352"/>
    </inertial>
    <visual>
      <origin rpy="0 0 0" xyz="0.175496 -0.080881 0.0873"/>
      <geometry>
        <mesh filename="package://spiderbot_description/meshes/femur_RR_1.stl" scale="0.001 0.001 0.001"/>
      </geometry>
      <material name="rear_red"/>
    </visual>
    <collision>
      <origin rpy="0 0 0" xyz="0.175496 -0.080881 0.0873"/>
      <geometry>
        <mesh filename="package://spiderbot_description/meshes/femur_RR_1.stl" scale="0.001 0.001 0.001"/>
      </geometry>
    </collision>
  </link>
  <link name="rr_tibia_link">
    <inertial>
      <origin rpy="0 0 0" xyz="0.015570071022172893 0.025956642235597266 -0.044292770387241207"/>
      <mass value="0.8577979430954783"/>
      <inertia ixx="0.0017" ixy="-1.3e-05" ixz="-7.6e-05" iyy="0.001667" iyz="6.5e-05" izz="0.000147"/>
    </inertial>
    <visual>
      <origin rpy="0 0 0" xyz="0.232064 -0.137449 0.0873"/>
      <geometry>
        <mesh filename="package://spiderbot_description/meshes/tibia_RR_1.stl" scale="0.001 0.001 0.001"/>
      </geometry>
      <material name="rear_red"/>
    </visual>
    <collision>
      <origin rpy="0 0 0" xyz="0.232064 -0.137449 0.0873"/>
      <geometry>
        <mesh filename="package://spiderbot_description/meshes/tibia_RR_1.stl" scale="0.001 0.001 0.001"/>
      </geometry>
    </collision>
  </link>
  <!-- ============================================ -->
  <!-- JOINTS - FRONT LEFT LEG -->
  <!-- ============================================ -->
  <joint name="fl_coxa_joint" type="revolute">
    <origin rpy="0 0 0" xyz="0.0802 -0.1049 -0.0717"/>
    <parent link="base_link"/>
    <child link="fl_coxa_link"/>
    <axis xyz="-0.0 -0.0 1.0"/>
    <limit effort="100" lower="-1.570796" upper="1.570796" velocity="10"/>
    <dynamics damping="0.1" friction="0.1"/>
  </joint>
  <joint name="fl_femur_joint" type="revolute">
    <origin rpy="0 0 0" xyz="0.055296 -0.015981 -0.0171"/>
    <parent link="fl_coxa_link"/>
    <child link="fl_femur_link"/>
    <axis xyz="0.707107 0.707107 -0.0"/>
    <limit effort="100" lower="-1.570796" upper="1.570796" velocity="10"/>
    <dynamics damping="0.1" friction="0.1"/>
  </joint>
  <joint name="fl_tibia_joint" type="revolute">
    <origin rpy="0 0 0" xyz="0.056568 -0.056568 0.0"/>
    <parent link="fl_femur_link"/>
    <child link="fl_tibia_link"/>
    <axis xyz="-0.707107 -0.707107 0.0"/>
    <limit effort="100" lower="-1.570796" upper="1.570796" velocity="10"/>
    <dynamics damping="0.1" friction="0.1"/>
  </joint>
  <!-- ============================================ -->
  <!-- JOINTS - FRONT RIGHT LEG -->
  <!-- ============================================ -->
  <joint name="fr_coxa_joint" type="revolute">
    <origin rpy="0 0 0" xyz="-0.1202 -0.10365 -0.07235"/>
    <parent link="base_link"/>
    <child link="fr_coxa_link"/>
    <axis xyz="0.0 0.0 1.0"/>
    <limit effort="100" lower="-1.570796" upper="1.570796" velocity="10"/>
    <dynamics damping="0.1" friction="0.1"/>
  </joint>
  <joint name="fr_femur_joint" type="revolute">
    <origin rpy="0 0 0" xyz="-0.015981 -0.055296 -0.0171"/>
    <parent link="fr_coxa_link"/>
    <child link="fr_femur_link"/>
    <axis xyz="0.707107 -0.707107 -0.0"/>
    <limit effort="100" lower="-1.570796" upper="1.570796" velocity="10"/>
    <dynamics damping="0.1" friction="0.1"/>
  </joint>
  <joint name="fr_tibia_joint" type="revolute">
    <origin rpy="0 0 0" xyz="-0.055507 -0.057629 0.0"/>
    <parent link="fr_femur_link"/>
    <child link="fr_tibia_link"/>
    <axis xyz="0.707107 -0.707107 -0.0"/>
    <limit effort="100" lower="-1.570796" upper="1.570796" velocity="10"/>
    <dynamics damping="0.1" friction="0.1"/>
  </joint>
  <!-- ============================================ -->
  <!-- JOINTS - REAR LEFT LEG -->
  <!-- ============================================ -->
  <joint name="rl_coxa_joint" type="revolute">
    <origin rpy="0 0 0" xyz="0.0802 0.0649 -0.0717"/>
    <parent link="base_link"/>
    <child link="rl_coxa_link"/>
    <axis xyz="0.0 -0.0 1.0"/>
    <limit effort="100" lower="-1.570796" upper="1.570796" velocity="10"/>
    <dynamics damping="0.1" friction="0.1"/>
  </joint>
  <joint name="rl_femur_joint" type="revolute">
    <origin rpy="0 0 0" xyz="0.015981 0.055296 -0.0171"/>
    <parent link="rl_coxa_link"/>
    <child link="rl_femur_link"/>
    <axis xyz="-0.707107 0.707107 0.0"/>
    <limit effort="100" lower="-1.570796" upper="1.570796" velocity="10"/>
    <dynamics damping="0.1" friction="0.1"/>
  </joint>
  <joint name="rl_tibia_joint" type="revolute">
    <origin rpy="0 0 0" xyz="0.056568 0.056568 0.0"/>
    <parent link="rl_femur_link"/>
    <child link="rl_tibia_link"/>
    <axis xyz="-0.707107 0.707107 0.0"/>
    <limit effort="100" lower="-1.570796" upper="1.570796" velocity="10"/>
    <dynamics damping="0.1" friction="0.1"/>
  </joint>
  <!-- ============================================ -->
  <!-- JOINTS - REAR RIGHT LEG -->
  <!-- ============================================ -->
  <joint name="rr_coxa_joint" type="revolute">
    <origin rpy="0 0 0" xyz="-0.1202 0.0649 -0.0717"/>
    <parent link="base_link"/>
    <child link="rr_coxa_link"/>
    <axis xyz="0.0 0.0 1.0"/>
    <limit effort="100" lower="-1.570796" upper="1.570796" velocity="10"/>
    <dynamics damping="0.1" friction="0.1"/>
  </joint>
  <joint name="rr_femur_joint" type="revolute">
    <origin rpy="0 0 0" xyz="-0.055296 0.015981 -0.0156"/>
    <parent link="rr_coxa_link"/>
    <child link="rr_femur_link"/>
    <axis xyz="-0.707107 -0.707107 0.0"/>
    <limit effort="100" lower="-1.570796" upper="1.570796" velocity="10"/>
    <dynamics damping="0.1" friction="0.1"/>
  </joint>
  <joint name="rr_tibia_joint" type="revolute">
    <origin rpy="0 0 0" xyz="-0.056568 0.056568 0.0"/>
    <parent link="rr_femur_link"/>
    <child link="rr_tibia_link"/>
    <axis xyz="-0.707107 -0.707107 -0.0"/>
    <limit effort="100" lower="-1.570796" upper="1.570796" velocity="10"/>
    <dynamics damping="0.1" friction="0.1"/>
  </joint>
  <!-- ============================================ -->
  <!-- ROS2_CONTROL CONFIGURATION -->
  <!-- This replaces the old transmission system -->
  <!-- ============================================ -->
  <ros2_control name="SpiderHW" type="system">
    <hardware>
      <!-- Gazebo (Ignition/Fortress/Garden) ros2_control backend -->
      <plugin>gz_ros2_control/GazeboSimSystem</plugin>
    </hardware>
    <!-- Front Left Leg -->
    <joint name="fl_coxa_joint">
      <command_interface name="position"/>
      <state_interface name="position"/>
      <state_interface name="velocity"/>
      <state_interface name="effort"/>
    </joint>
    <joint name="fl_femur_joint">
      <command_interface name="position"/>
      <state_interface name="position"/>
      <state_interface name="velocity"/>
      <state_interface name="effort"/>
    </joint>
    <joint name="fl_tibia_joint">
      <command_interface name="position"/>
      <state_interface name="position"/>
      <state_interface name="velocity"/>
      <state_interface name="effort"/>
    </joint>
    <!-- Front Right Leg -->
    <joint name="fr_coxa_joint">
      <command_interface name="position"/>
      <state_interface name="position"/>
      <state_interface name="velocity"/>
      <state_interface name="effort"/>
    </joint>
    <joint name="fr_femur_joint">
      <command_interface name="position"/>
      <state_interface name="position"/>
      <state_interface name="velocity"/>
      <state_interface name="effort"/>
    </joint>
    <joint name="fr_tibia_joint">
      <command_interface name="position"/>
      <state_interface name="position"/>
      <state_interface name="velocity"/>
      <state_interface name="effort"/>
    </joint>
    <!-- Rear Left Leg -->
    <joint name="rl_coxa_joint">
      <command_interface name="position"/>
      <state_interface name="position"/>
      <state_interface name="velocity"/>
      <state_interface name="effort"/>
    </joint>
    <joint name="rl_femur_joint">
      <command_interface name="position"/>
      <state_interface name="position"/>
      <state_interface name="velocity"/>
      <state_interface name="effort"/>
    </joint>
    <joint name="rl_tibia_joint">
      <command_interface name="position"/>
      <state_interface name="position"/>
      <state_interface name="velocity"/>
      <state_interface name="effort"/>
    </joint>
    <!-- Rear Right Leg -->
    <joint name="rr_coxa_joint">
      <command_interface name="position"/>
      <state_interface name="position"/>
      <state_interface name="velocity"/>
      <state_interface name="effort"/>
    </joint>
    <joint name="rr_femur_joint">
      <command_interface name="position"/>
      <state_interface name="position"/>
      <state_interface name="velocity"/>
      <state_interface name="effort"/>
    </joint>
    <joint name="rr_tibia_joint">
      <command_interface name="position"/>
      <state_interface name="position"/>
      <state_interface name="velocity"/>
      <state_interface name="effort"/>
    </joint>
  </ros2_control>
  <!-- ============================================ -->
  <!-- GAZEBO ROS2_CONTROL PLUGIN -->
  <!-- ============================================ -->
  <gazebo>
    <plugin filename="gz_ros2_control-system" name="gz_ros2_control::GazeboSimROS2ControlPlugin">
      <parameters>/home/teja/spiderbot_ws/install/spiderbot_description/share/spiderbot_description/config/controllers.yaml</parameters>
      <robot_param>robot_description</robot_param>
      <robot_param_node>robot_state_publisher</robot_param_node>
      <controller_manager_name>controller_manager</controller_manager_name>
    </plugin>
  </gazebo>
  <gazebo reference="base_link">
    <material>Gazebo/Silver</material>
    <mu1>0.5</mu1>
    <mu2>0.5</mu2>
    <selfCollide>false</selfCollide>
    <gravity>true</gravity>
  </gazebo>
  <gazebo reference="fl_coxa_link">
    <material>Gazebo/Silver</material>
    <mu1>0.6</mu1>
    <mu2>0.6</mu2>
    <selfCollide>false</selfCollide>
  </gazebo>
  <gazebo reference="fl_femur_link">
    <material>Gazebo/Silver</material>
    <mu1>0.6</mu1>
    <mu2>0.6</mu2>
    <selfCollide>false</selfCollide>
  </gazebo>
  <gazebo reference="fl_tibia_link">
    <material>Gazebo/Silver</material>
    <mu1>0.6</mu1>
    <mu2>0.6</mu2>
    <selfCollide>false</selfCollide>
  </gazebo>
  <gazebo reference="fr_coxa_link">
    <material>Gazebo/Silver</material>
    <mu1>0.6</mu1>
    <mu2>0.6</mu2>
    <selfCollide>false</selfCollide>
  </gazebo>
  <gazebo reference="fr_femur_link">
    <material>Gazebo/Silver</material>
    <mu1>0.6</mu1>
    <mu2>0.6</mu2>
    <selfCollide>false</selfCollide>
  </gazebo>
  <gazebo reference="fr_tibia_link">
    <material>Gazebo/Silver</material>
    <mu1>0.6</mu1>
    <mu2>0.6</mu2>
    <selfCollide>false</selfCollide>
  </gazebo>
  <gazebo reference="rl_coxa_link">
    <material>Gazebo/Silver</material>
    <mu1>0.6</mu1>
    <mu2>0.6</mu2>
    <selfCollide>false</selfCollide>
  </gazebo>
  <gazebo reference="rl_femur_link">
    <material>Gazebo/Silver</material>
    <mu1>0.6</mu1>
    <mu2>0.6</mu2>
    <selfCollide>false</selfCollide>
  </gazebo>
  <gazebo reference="rl_tibia_link">
    <material>Gazebo/Silver</material>
    <mu1>0.6</mu1>
    <mu2>0.6</mu2>
    <selfCollide>false</selfCollide>
  </gazebo>
  <gazebo reference="rr_coxa_link">
    <material>Gazebo/Silver</material>
    <mu1>0.6</mu1>
    <mu2>0.6</mu2>
    <selfCollide>false</selfCollide>
  </gazebo>
  <gazebo reference="rr_femur_link">
    <material>Gazebo/Silver</material>
    <mu1>0.6</mu1>
    <mu2>0.6</mu2>
    <selfCollide>false</selfCollide>
  </gazebo>
  <gazebo reference="rr_tibia_link">
    <material>Gazebo/Silver</material>
    <mu1>0.6</mu1>
    <mu2>0.6</mu2>
    <selfCollide>false</selfCollide>
  </gazebo>
  <!-- ============================================ -->
  <!-- IMU SENSOR -->
  <!-- ============================================ -->
  <gazebo reference="base_link">
    <sensor name="imu_sensor" type="imu">
      <always_on>true</always_on>
      <update_rate>100</update_rate>
      <topic>imu</topic>
      <gz_frame_id>base_link</gz_frame_id>
    </sensor>
  </gazebo>
</robot>
